Workbook

Sheet info sheet
A3: Name Market
A4: Location (address)
A5: Coordinates (if possible)
A6: Country
A8: Current Assessment
A9: Date
A10: Assessor
A11: Affiliation
A13: Previous assessment 1
A14: Date
A15: Assessor
A16: Affiliation
... A48: free roaming reservoir animals (rats etc)

Sheet raw data
A1: Market Mapping Tool (MMT) - MATRIX
A3: CATEGORIES | B3: Indicators | C3: Score 1 (Low) | D3: Score 2 | E3: Score 3 | F3: Score 4 (High) | G3: Score | H3: Average for category | I3: % | K3: Previous Score 1 | L3: Average for category | M3: % | O3: Previous Score 2 | P3: Average for category | Q3: %
A4: Category 1: Governance, Regulation, and Market Management | B4: Is there any oversight by veterinary and public‑health authorities using official policy documents? | C4: There is no formal oversight by veterinary or public‑health authorities, and no official policy documents are applied or referenced at the market level. | D4: Some oversight exists, but it is irregular, informal, or based on outdated or incomplete policy documents, with limited authority presence. | E4: Oversight by veterinary and/or public‑health authorities is established and guided by official policy documents, but implementation is inconsistent or limited in scope. | F4: Regular and coordinated oversight by veterinary and public‑health authorities is conducted using up‑to‑date official policy documents, with clear mandates and routine supervision. | G4: 4 | H4: =AVERAGE(G4:G10) -> 3.5 | I4: =H4/4*100 -> 87.5 | K4: 4 | L4: =AVERAGE(K4:K10) -> 3.5 | M4: =L4/4*100 -> 87.5 | O4: 4 | P4: =AVERAGE(O4:O10) -> 3.5 | Q4: =P4/4*100 -> 87.5
B5: Is there any licensing or registration of the market and its vendors? | C5: Neither the market nor its vendors are licensed or registered with any competent authority. | D5: The market and/or some vendors are registered or licensed, but the process is incomplete, outdated, or weakly enforced. | E5: The market is licensed and most vendors are registered, but records are not always updated or systematically verified. | F5: The market and all vendors are formally licensed and registered, with updated records that are routinely verified and enforced by authorities. | G5: 4 | K5: 4 | O5: 4
B6: Is there a market management committee or designated authority present AND sufficiently funded to maintain market operations? | C6: No market management committee or designated authority exists, or it exists only in name without funding or operational capacity. | D6: A committee or designated authority exists, but funding is insufficient to effectively manage or maintain market operations. | E6: A management committee or authority is present and funded, but resources are limited and operational effectiveness is inconsistent. | F6: A functional market management committee or designated authority is in place, adequately funded, and able to effectively maintain and manage market operations. | G6: 2 | K6: 2 | O6: 2
B7: Is there any policy enforcement on hygiene, animal welfare, disease‑control regulations? | C7: No enforcement of hygiene, animal welfare, or disease‑control regulations is observed, despite policies existing at national or local level. | D7: Enforcement occurs sporadically, is reactive, or depends on individual inspectors rather than systematic procedures. | E7: Policies are enforced regularly, but enforcement may be uneven across the market or weakened during peak periods. | F7: Hygiene, animal welfare, and disease‑control regulations are consistently enforced through routine inspections, clear penalties, and documented follow‑up actions. | G7: 4 | K7: 4 | O7: 4
B8: Do market‑level rules/by‑laws exist and are they aligned with national policies? | C8: No market‑level rules or by‑laws exist, or existing rules are not aligned with national policies. | D8: Market‑level rules or by‑laws exist but are only partially aligned with national policies or poorly communicated to market users. | E8: Market‑level rules and by‑laws are largely aligned with national policies, but enforcement or periodic review is limited. | F8: Market‑level rules and by‑laws are fully aligned with national policies, well communicated, regularly reviewed, and effectively enforced.
B9: Are there market level SOPs for cleaning, disinfection, slaughter, animal and waste handling? | C9: No SOPs exist for cleaning, disinfection, slaughter, animal handling, or waste management, and practices are informal. | D9: SOPs exist but are incomplete, outdated, or known only by a small number of actors, with limited implementation. | E9: SOPs are available and generally followed, but compliance varies and monitoring is irregular. | F9: Comprehensive SOPs are in place, up‑to‑date, widely disseminated, consistently implemented, and routinely monitored for compliance. | G9: 3 | K9: 3 | O9: 3
B10: Is there any cross‑sectoral collaboration at market level between public health, animal health, and judicial authorities? | C10: No collaboration exists between public health, animal health, and judicial authorities at market level. | D10: Limited collaboration occurs on an ad‑hoc basis, usually during outbreaks or enforcement actions. | E10: Regular collaboration exists between sectors, but coordination mechanisms are informal or not fully institutionalized. | F10: Formal, institutionalized cross‑sectoral collaboration exists, with regular coordination, information sharing, and joint action at market level. | G10: 4 | K10: 4 | O10: 4
A11: Category 2: Infrastructure and Facilities | B11: Is there an adequate physical layout including species segregation, separation of slaughter and retail zones? | C11: There is no physical layout planning; species are mixed, and slaughter occurs in the same areas as retail without separation. | D11: Some informal separation exists between species or functions, but it is not enforced, and layout is poorly organized. | E11: The layout includes basic separation between species, slaughter, and retail zones, but the infrastructure or signage is limited. | F11: The market has a well‑defined physical layout with clear, enforced segregation of species, and distinct areas for slaughter and retail activities. | G11: 2 | H11: =AVERAGE(G11:G16) -> 3 | I11: =H11/4*100 -> 75 | K11: 2 | L11: =AVERAGE(K11:K16) -> 3 | M11: =L11/4*100 -> 75 | O11: 2 | P11: =AVERAGE(O11:O16) -> 3 | Q11: =P11/4*100 -> 75
B12: Is there adequate drainage for waste water management and solid waste and carcass disposal by product? | C12: There is no functioning drainage system; wastewater and waste accumulate in open areas, with no structured disposal. | D12: Drainage exists but is poorly designed, often clogged, or not maintained; disposal of solid waste and carcasses is irregular. | E12: Drainage is mostly functional; some systems are in place for disposal by product, but practices vary and oversight is weak. | F12: Drainage and waste management systems are well maintained, with appropriate collection, segregation, and disposal by product type. | G12: 4 | K12: 4 | O12: 4
B13: Is there access to hand‑washing with disinfection (soap) stations? | C13: There are no handwashing facilities with soap or disinfectant available in the market. | D13: Handwashing stations exist but may lack soap, disinfectant, or are inaccessible to most vendors and customers. | E13: Handwashing stations with disinfectant are available in key areas, but not consistently stocked or maintained. | F13: Clean, functional handwashing stations with soap or disinfectant are available, accessible, and routinely supplied throughout the market. | G13: 3 | K13: 3 | O13: 3
B14: Is there sufficient power and ventilation? | C14: There is no reliable power supply, and ventilation is inadequate in enclosed areas of the market. | D14: Power or ventilation exists but is unreliable, insufficient, or not maintained. | E14: Basic power and ventilation are present and functional in most areas, but coverage may be inconsistent. | F14: Adequate and reliable power and ventilation are provided throughout the market, ensuring proper lighting, airflow, and equipment use. | G14: 4 | K14: 4 | O14: 4
B15: Is there cold storage or chilling units for products available? | C15: No cold storage or chilling units are present; perishable products are kept at ambient temperature. | D15: Cold storage exists but is limited in capacity, not functioning properly, or inaccessible to most vendors. | E15: Functional chilling units are available and used by some vendors, but may not meet full market demand. | F15: Sufficient, well-maintained cold storage and chilling units are available and accessible for all vendors handling perishable products. | G15: 4 | K15: 4 | O15: 4
B16: Are the floors and surfaces washeable? | C16: Floors and surfaces are not wash‑friendly; materials are porous, cracked, or damaged, making cleaning difficult. | D16: Some areas have washable surfaces, but others remain unhygienic or made of inappropriate materials. | E16: Most market surfaces are washable and regularly cleaned, but some structural issues or gaps remain. | F16: All floors and surfaces are made of durable, washable materials and are cleaned regularly as part of standard sanitation practices. | G16: 1 | K16: 1 | O16: 1
A17: Category 3: Biosecurity, Hygiene and Sanitary Practices | B17: Is there clear separation of animals (species, feral) and market practices (animal holding, slaughter, sales area)? | C17: There is no separation between animal species, feral animals, or between slaughter, holding, and sales areas. Activities are mixed with high cross-contamination risk. | D17: Some separation exists, but boundaries are informal or unenforced; feral animals may roam freely. | E17: Separation of animal types and market functions exists, but some practices or zones overlap; enforcement may be inconsistent. | F17: There is clear, enforced physical and procedural separation of species (including feral animals) and all market practices (holding, slaughter, sales), reducing transmission risks. | G17: 1 | H17: =AVERAGE(G17:G22) -> 3 | I17: =H17/4*100 -> 75 | K17: 1 | L17: =AVERAGE(K17:K22) -> 3 | M17: =L17/4*100 -> 75 | O17: 1 | P17: =AVERAGE(O17:O22) -> 3 | Q17: =P17/4*100 -> 75
B18: Are there routine cleaning and disinfection schedules for market facilities (cages, equipment, transport containers, holding pens)? | C18: There are no cleaning or disinfection schedules; activities are ad hoc or reactive to complaints. | D18: Schedules exist but are irregular or only partially followed; certain facilities may be neglected. | E18: Routine cleaning and disinfection are carried out on a scheduled basis, though monitoring or consistency may vary. | F18: Comprehensive cleaning and disinfection are conducted on a routine schedule for all facilities, with records and oversight ensuring adherence. | G18: 4 | K18: 4 | O18: 4
B19: Is PPE (gloves, masks, aprons) accessible and used by vendors and market workers? | C19: PPE is not available, or vendors and workers are unaware or unwilling to use it. | D19: Some PPE is available but limited in quantity, type, or only used during inspections. | E19: PPE is generally available and used by most market actors, though not always consistently or appropriately. | F19: PPE is fully accessible and used consistently and correctly by all vendors and workers during relevant activities, in line with training and guidance. | G19: 2 | K19: 2 | O19: 2
B20: Are there procedures for managing sick or dead animals? | C20: No procedures exist; sick or dead animals remain in the market or are disposed of informally. | D20: Informal procedures are used inconsistently and without guidance from veterinary or health authorities. | E20: Procedures are in place and usually followed, but gaps remain in monitoring or disposal practices. | F20: Standard procedures for reporting, isolating, removing, and disposing of sick or dead animals are in place, enforced, and understood by all market actors. | G20: 3 | K20: 3 | O20: 3
B21: Are there rest days for thorough cleaning and disinfection? Are any animals staying overnight? | C21: No rest days are scheduled, and animals routinely stay overnight with no biosecurity controls. | D21: Occasional rest days are designated, but implementation is inconsistent, and animals may still remain onsite. | E21: Rest days occur on a regular schedule and most animals are removed, but some remain due to operational constraints. | F21: Rest days are consistently scheduled and used for thorough cleaning and disinfection; no animals remain onsite overnight unless in secure, biosecure holding facilities. | G21: 4 | K21: 4 | O21: 4
B22: Is there frequent hand hygiene among workers and vendors? | C22: Hand hygiene is not practiced; there is no access to soap, water, or handwashing infrastructure. | D22: Hand hygiene is practiced occasionally; soap or handwashing stations are present but underused. | E22: Hand hygiene is practiced by most workers and vendors, especially during risk activities, though gaps remain. | F22: Hand hygiene is frequently and consistently practiced by all market workers and vendors, supported by infrastructure and behavioral reinforcement. | G22: 4 | K22: 4 | O22: 4
A23: Category 4: Zoonotic Risk Factors | B23: What is the presence of high‐risk species and level of species mixing? Are farmed and wild-captured animals present and separated? | C23: High-risk species are present and mixed without any separation; wild and farmed animals are kept together. | D23: High-risk species are present and partially separated, but enforcement is weak or inconsistent. | E23: High-risk species are separated from others, and wild/farmed animals are kept apart in most areas. | F23: High-risk species are either absent or strictly separated; wild-captured and farmed animals are fully segregated with clear enforcement. | G23: 2 | H23: =AVERAGE(G23:G31) -> 1.2 | I23: =H23/4*100 -> 30 | K23: 2 | L23: =AVERAGE(K23:K31) -> 1.2 | M23: =L23/4*100 -> 30 | O23: 2 | P23: =AVERAGE(O23:O31) -> 1.2 | Q23: =P23/4*100 -> 30
B24: What is the duration animals held before sale or slaughter, and in what conditions (density) are animals kept? | C24: Animals are kept for prolonged periods in overcrowded, unsanitary conditions without consideration for welfare or health. | D24: Animals are held for variable periods; some overcrowding is observed, and welfare conditions are inconsistent. | E24: Holding durations are controlled, and most animals are kept in appropriate density and environmental conditions. | F24: Animals are held only for short, defined durations under species-appropriate density, ventilation, and welfare standards. | G24: 1 | K24: 1 | O24: 1
B25: Are there slaughtering practices within the market premises? | C25: Slaughtering occurs on-site without designated areas, hygiene controls, or supervision. | D25: Slaughtering takes place within the market but in loosely defined or multi-use areas. | E25: Dedicated slaughter areas are in place, though oversight or hygiene control may vary. | F25: Slaughtering occurs only in designated, hygienic, and supervised areas that are separated from live animal zones. No slaughtering of animals. | G25: 1 | K25: 1 | O25: 1
B26: What is the proximity to wetlands or wildlife habitats? | C26: The market is adjacent to or within known wildlife habitats or wetlands, no mitigation (fencing) is present, creating a high risk of pathogen spillover. | D26: The market is near such habitats, but some mitigation (e.g. fencing or buffer zones) is in place. | E26: The market is located at a moderate distance with good separation or buffer from wildlife areas. | F26: The market is located far from wetlands or wildlife habitats, with environmental buffers or barriers in place. | G26: 1 | K26: 1 | O26: 1
B27: Are there any vector species (insects, rodents) present? | C27: Vector species such as flies and rodents are widespread, with no control measures in place. | D27: Vector species are present but basic control (e.g. traps) is attempted inconsistently. | E27: Some control measures reduce vector populations, limited presence is still observed in specific zones. | F27: Vector species are rarely observed due to regular pest control programs and structural safeguards.
B28: Are animals kept overnight? | C28: Many animals remain onsite overnight in the open or in unsanitary, insecure holding areas. | D28: Some animals are kept overnight in shared or inappropriate facilities. | E28: Most animals are removed at end of day, or kept in enclosed areas with basic biosecurity. | F28: Animals are either removed daily or held overnight in secure, biosecure, species-appropriate enclosures.
B29: Are there any sick or dead animals present in the market? | C29: Sick or dead animals are visible in the market without isolation or proper removal procedures. | D29: Sick or dead animals are present but are removed only after delays or public complaints. | E29: Sick or dead animals are rarely present, and protocols for their removal are usually followed. | F29: No sick or dead animals are observed due to effective early detection, isolation, and removal procedures.
B30: How many different sources do animals come from? | C30: Animals are sourced from multiple unknown or unregistered locations, with no documentation or traceability. | D30: Animals come from a mix of sources, some of which are traceable, but records are inconsistent. | E30: Most animals come from known, documented sources with partial traceability. | F30: All animals originate from approved, registered sources with full documentation and traceability.
B31: Are there signs of environmental contamination (blood, feathers, faeces) visible? | C31: Extensive contamination with visible blood, feathers, and faeces is observed throughout the market. | D31: Contamination is visible in several areas despite some cleaning efforts. | E31: Minor contamination is observed and cleaning appears routine but could be improved. | F31: Market is visibly clean and well maintained, with minimal signs of contamination and clear sanitation practices. | G31: 1 | K31: 1 | O31: 1
A32: Category 5: Surveillance and Reporting | B32: Is there any active or passive disease surveillance in the market? | C32: No surveillance (active or passive) is conducted in or around the market. | D32: Passive surveillance exists informally, such as occasional observations by vendors or staff, but is not structured. | E32: Either active or passive surveillance is implemented regularly by responsible authorities or designated actors. | F32: Both active and passive surveillance are routinely and systematically conducted by trained personnel using a defined protocol. | G32: 4 | H32: =AVERAGE(G32:G40) -> 2.2 | I32: =H32/4*100 -> 55 | K32: 4 | L32: =AVERAGE(K32:K40) -> 2.2 | M32: =L32/4*100 -> 55 | O32: 4 | P32: =AVERAGE(O32:O40) -> 2.2 | Q32: =P32/4*100 -> 55
B33: Is there a legal framework for sampling, surveillance and data-sharing? | C33: There is no legal or policy framework supporting surveillance, sampling, or data-sharing at the market level. | D33: A basic framework exists but is outdated, fragmented, or poorly known by stakeholders. | E33: A legal or regulatory framework exists and is partially implemented, but awareness or compliance varies. | F33: A formal, current legal framework exists and is well implemented, ensuring clear protocols for sampling, surveillance, and inter-agency data-sharing.
B34: Are there clear objectives for the surveillance activities in the market? | C34: Surveillance activities are unstructured, with no defined objectives or priorities. | D34: Some objectives exist but are vague, undocumented, or not known to those conducting surveillance. | E34: Objectives are defined and known by relevant actors, though not always linked to clear indicators or market risks. | F34: Surveillance is guided by clear, measurable objectives that are risk-based and aligned with public health and veterinary priorities.
B35: Is there timely reporting of surveillance activities and is there a loop-back mechanism to the community? Are disease detection or case reporting mechanisms present? | C35: No reporting systems exist, and market actors are not informed of surveillance findings. | D35: Surveillance reports are prepared but not shared with the community or shared with significant delay. | E35: Reporting occurs in a timely manner and some feedback reaches market actors, though mechanisms are informal. | F35: Surveillance findings are reported promptly with an effective feedback loop to vendors, managers, and local stakeholders, enabling awareness and action.
B36: Is there submission of animal or environmental samples for laboratory testing followed by appropriate data analysis? | C36: No samples are collected for laboratory testing from the market. | D36: Samples are occasionally collected but without systematic testing or analysis. | E36: Animal or environmental samples are submitted regularly and basic analysis is performed. | F36: Sample collection is routine and leads to structured laboratory testing with follow-up epidemiological analysis and reporting. | G36: 4 | K36: 4 | O36: 4
B37: Are there any clear actions from surveillance and reporting? | C37: No actions are taken as a result of surveillance findings, even if risks are identified. | D37: Actions are taken occasionally, often delayed or reactive, and lack consistency. | E37: Actions based on surveillance are implemented, though follow-up may be partial or unmonitored. | F37: Surveillance triggers defined, timely response actions with accountability, documentation, and follow-through.
B38: Are digital or manual early‑warning and data‑systems used? | C38: No data systems (manual or digital) are used for surveillance or warning. | D38: Basic manual records are kept but not centralized or shared. | E38: Either digital or manual systems are used for recording and tracking events and cases. | F38: Well-functioning digital or integrated systems are used for early warning, real-time data sharing, and coordination. | G38: 1 | K38: 1 | O38: 1
B39: Is there coordination with animal and public‑health authorities? (integrated One Health surveillance?) | C39: No coordination exists between animal health and public health authorities on surveillance. | D39: Limited coordination takes place occasionally, with no formal framework or regular interaction. | E39: Some coordination mechanisms are in place, such as joint meetings or information exchange, but may lack institutionalization. | F39: Integrated One Health surveillance is in place, with regular, formal coordination between animal and public health authorities. | G39: 1 | K39: 1 | O39: 1
B40: Is the history of zoonotic/pathogen detection in the market known and recorded? | C40: There is no record or awareness of previous zoonotic or pathogen detections in the market. | D40: Some knowledge exists based on informal memory or non-documented reports. | E40: Records of past detections are partially available and referenced occasionally. | F40: A clear and accessible record of pathogen detections and zoonotic events is maintained, reviewed, and used to inform current practices. | G40: 1 | K40: 1 | O40: 1
A41: Category 6: Risk Communication and Awareness | B41: Are there culturally appropriate signage and IEC (Information, Education, and Communication) materials on hygiene and disease prevention available? | C41: No signage or IEC materials are available in the market. | D41: Some signage or IEC materials are present, but they are generic, outdated, or not locally relevant. | E41: Culturally appropriate IEC materials are present in key locations, but may not fully address all hygiene and disease prevention needs. | F41: Comprehensive, culturally tailored IEC materials and signage on hygiene and disease prevention are prominently displayed and regularly updated throughout the market. | G41: 2 | H41: =AVERAGE(G41:G45) -> 2.4 | I41: =H41/4*100 -> 60 | K41: 2 | L41: =AVERAGE(K41:K45) -> 2.4 | M41: =L41/4*100 -> 60 | O41: 2 | P41: =AVERAGE(O41:O45) -> 2.4 | Q41: =P41/4*100 -> 60
...

Sheet analysis
A2: Table - main categories
B3: current score
A4: category | B4: %
A5: Governance, Regulation, and Market Management | B5: ='raw data'!I4 -> 87.5
A6: Infrastructure and Facilities | B6: ='raw data'!I11 -> 75
A7: Biosecurity and Hygiene Practices | B7: ='raw data'!I17 -> 75
A8: Zoonotic Risk Factors | B8: ='raw data'!I23 -> 30
A9: Surveillance and Reporting | B9: ='raw data'!I32 -> 55
A10: Risk Communication and Awareness | B10: ='raw data'!I41 -> 60
A11: Market Connectivity and Trade Dynamics | B11: ='raw data'!I46 -> 66.666667
A12: Emergency Preparedness and Risk Mitigation | B12: ='raw data'!I51 -> 50
A13: Stakeholder Engagement | B13: ='raw data'!I59 -> 33.333333
A15: Overall score | B15: =AVERAGE(B5:B13) -> 59.166667
B24: current score | C24: previous 1 | D24: previous 2
A25: category | B25: % | C25: % | D25: %
A26: Governance, Regulation, and Market Management | B26: =B5 -> 87.5 | C26: ='raw data'!M4 -> 87.5 | D26: ='raw data'!Q4 -> 87.5
A27: Infrastructure and Facilities | B27: =B6 -> 75 | C27: ='raw data'!M11 -> 75 | D27: ='raw data'!Q11 -> 75
A28: Biosecurity and Hygiene Practices | B28: =B7 -> 75 | C28: ='raw data'!M17 -> 75 | D28: ='raw data'!Q17 -> 75
A29: Zoonotic Risk Factors | B29: =B8 -> 30 | C29: ='raw data'!M23 -> 30 | D29: ='raw data'!Q23 -> 30
A30: Surveillance and Reporting | B30: =B9 -> 55 | C30: ='raw data'!M32 -> 55 | D30: ='raw data'!Q32 -> 55
A31: Risk Communication and Awareness | B31: =B10 -> 60 | C31: ='raw data'!M41 -> 60 | D31: ='raw data'!Q41 -> 60
A32: Market Connectivity and Trade Dynamics | B32: =B11 -> 66.666667 | C32: ='raw data'!M46 -> 66.666667 | D32: ='raw data'!Q46 -> 66.666667
A33: Emergency Preparedness and Risk Mitigation | B33: =B12 -> 50 | C33: ='raw data'!M51 -> 50 | D33: ='raw data'!Q51 -> 50
A34: Stakeholder Engagement | B34: =B13 -> 33.333333 | C34: ='raw data'!M59 -> 33.333333 | D34: ='raw data'!Q59 -> 33.333333
A36: Overall Score | B36: =AVERAGE(B26:B34) -> 59.166667 | C36: =AVERAGE(C26:C34) -> 59.166667 | D36: =AVERAGE(D26:D34) -> 59.166667
